<mujoco model="terafacMini">
  <compiler angle="radian" autolimits="true"/>

  <default>
    <!-- Changed damping to dof_damping -->
    <joint type="hinge" frictionloss="0.1" armature="0.1" limited="true"/>
    <default class="visual">
      <geom type="mesh"/>
    </default>
    <position ctrllimited="true"/>
  </default>

  <option integrator="implicitfast">
    <flag contact="disable"/>
  </option>

  <asset>
    <mesh name="base" file="./meshes/base.obj" scale="0.001 0.001 0.001"/>
    <mesh name="link1" file="./meshes/link1.obj" scale="0.001 0.001 0.001"/>
    <mesh name="link2" file="./meshes/link2.obj" scale="0.001 0.001 0.001"/>
    <mesh name="link3" file="./meshes/link3.obj" scale="0.001 0.001 0.001"/>
    <mesh name="link4" file="./meshes/link4.obj" scale="0.001 0.001 0.001"/>
    <mesh name="link5" file="./meshes/link5.obj" scale="0.001 0.001 0.001"/>
    <mesh name="link6" file="./meshes/link6.obj" scale="0.001 0.001 0.001"/>
  </asset>

  <worldbody>
    <camera name="tracker" pos="0.764 -0.430 0.671" xyaxes="0.491 0.871 -0.000 -0.530 0.298 0.794"/>
    <light name="top" pos="0 0 2" mode="trackcom"/>
    <body name="base" euler="0 0 3.12413936">      <!-- Matched URDF orientation -->
      <inertial mass="4.970684" pos="0 0 0" diaginertia="0.70337 0.70661 0.70337"/>
      <geom mesh="base" class="visual" />
      <body name="link1" pos="0.00045 0.00075 0.0675">
        <inertial mass="3.228604" pos="0 0 0" diaginertia="0.037242 0.036155 0.01083"/>
        <joint name="joint_1" type="hinge" axis="0 0 -1" range="-3.14 3.14"/>
        <geom mesh="link1" class="visual"/>

        <body name="link2" pos="-0.00001 0.0014 0.0475008" euler="0 -1.56275745 0">
          <inertial mass="3.587895" pos="0 0 0" diaginertia="0.025853 0.019552 0.028323"/>
          <joint name="joint_2" type="hinge" axis="0 -1 0" range="-1.57 1.57"/>
          <!-- Corrected range -->
          <geom mesh="link2" class="visual"/>

          <body name="link3" pos="0.2 -0.0264 0" euler="1.56275745 0 0">
            <inertial mass="1.225946" pos="0 0 0" diaginertia="0.035549 0.029474 0.008627"/>
            <joint name="joint_3" type="hinge" axis="0 0 1" range="-1.57 1.57"/>
            <!-- Corrected range -->
            <geom mesh="link3" class="visual"/>

            <body name="link4" pos=".01 .1074 -.0267" euler="-1.56275745 0 0">
              <inertial mass="1.666555" pos="0 0 0" diaginertia="0.001964 0.004354 0.005433"/>
              <joint name="joint_4" type="hinge" axis="0 0 -1" range="-3.14 3.14"/>
              <geom mesh="link4" class="visual"/>

              <body name="link5" pos="-0.0001 0.0172 .04767" euler="1.56275745 0 0">
                <inertial mass="1.225946" pos="0 0 0" diaginertia="0.035549 0.029474 0.008627"/>
                <joint name="joint_5" type="hinge" axis="0 0 -1" range="-1.57 1.57"/>
                <geom mesh="link5" class="visual"/>

                <body name="link6" pos=".00515 .0958 .01705" euler="-1.56275745 0 0">
                  <inertial mass="0.735522" pos="0 0 0" diaginertia="0.012516 0.010027 0.004815"/>
                  <joint name="joint_6" type="hinge" axis="0 0 -1" range="-3.14 3.14"/>
                  <geom mesh="link6" class="visual"/>

                  <!-- Added tool0 to match URDF -->
                  <body name="attachment" pos="-0.0156 0 .150889">
                    <site name="attachment_site" rgba="1 0 0 1" size=".001" group="1" quat="0 0 0 1"/>
                  </body>
                </body>
              </body>
            </body>
          </body>
        </body>
      </body>
    </body>
  </worldbody>

  <actuator>
    <!-- Using consistent friction and damping across all joints -->
    <position name="joint_1" joint="joint_1" ctrlrange="-3.14 3.14" kp="1000" kv="100"/>
    <position name="joint_2" joint="joint_2" ctrlrange="-1.57 1.57" kp="1000" kv="100"/>
    <position name="joint_3" joint="joint_3" ctrlrange="-1.57 1.57" kp="1000" kv="100"/>
    <position name="joint_4" joint="joint_4" ctrlrange="-3.14 3.14" kp="1000" kv="100"/>
    <position name="joint_5" joint="joint_5" ctrlrange="-1.57 1.57" kp="1000" kv="100"/>
    <position name="joint_6" joint="joint_6" ctrlrange="-3.14 3.14" kp="1000" kv="100"/>
  </actuator>

  <keyframe>
    <key name="home" qpos="0 0 0 0 0 0" ctrl="0 0 0 0 0 0"/>
  </keyframe>
</mujoco>